Workbook

Sheet Data
A1: post_id | B1: account_id | C1: niche | D1: post_date | E1: post_time | F1: post_type | G1: followers | H1: hashtag_count | I1: caption_length | J1: has_cta | K1: impressions | L1: reach | M1: likes | N1: comments | O1: shares | P1: saves | Q1: profile_visits | R1: follows_gained | S1: hour | T1: weekday | U1: engagement_rate | V1: time_slot
A2: P00808 | B2: acct_045 | C2: Fitness | D2: 45858 | E2: 10:30 | F2: Carousel | G2: 63447 | H2: 15 | I2: 338 | J2: 1 | K2: 71515 | L2: 62990 | M2: 2756 | N2: 113 | O2: 311 | P2: 452 | Q2: 1197 | R2: 322 | S2: 10 | T2: Sunday | U2: =(M2+N2+O2+P2)/L2 -> 0.057659946 | V2: =IF(S2<=5,"Late night (0-5)",IF(S2<=11,"Morning (6-11)",IF(S2<=17,"Afternoon (12-17)","Evening (18-23)"))) -> Morning (6-11)
A3: P01448 | B3: acct_024 | C3: Fashion | D3: 45985 | E3: 12:22 | F3: Reel | G3: 11612 | H3: 25 | I3: 10 | J3: 1 | K3: 18135 | L3: 13997 | M3: 769 | N3: 40 | O3: 112 | P3: 208 | Q3: 321 | R3: 89 | S3: 12 | T3: Monday | U3: =(M3+N3+O3+P3)/L3 -> 0.080660141 | V3: =IF(S3<=5,"Late night (0-5)",IF(S3<=11,"Morning (6-11)",IF(S3<=17,"Afternoon (12-17)","Evening (18-23)"))) -> Afternoon (12-17)
A4: P01992 | B4: acct_028 | C4: Education | D4: 45936 | E4: 08:17 | F4: Image | G4: 33933 | H4: 6 | I4: 60 | J4: 1 | K4: 32568 | L4: 26200 | M4: 1653 | N4: 113 | O4: 102 | P4: 84 | Q4: 213 | R4: 35 | S4: 8 | T4: Monday | U4: =(M4+N4+O4+P4)/L4 -> 0.074503817 | V4: =IF(S4<=5,"Late night (0-5)",IF(S4<=11,"Morning (6-11)",IF(S4<=17,"Afternoon (12-17)","Evening (18-23)"))) -> Morning (6-11)
A5: P01817 | B5: acct_015 | C5: Travel | D5: 45978 | E5: 12:25 | F5: Image | G5: 23051 | H5: 14 | I5: 29 | J5: 0 | K5: 20623 | L5: 12708 | M5: 651 | N5: 35 | O5: 112 | P5: 36 | Q5: 139 | R5: 26 | S5: 12 | T5: Monday | U5: =(M5+N5+O5+P5)/L5 -> 0.065627951 | V5: =IF(S5<=5,"Late night (0-5)",IF(S5<=11,"Morning (6-11)",IF(S5<=17,"Afternoon (12-17)","Evening (18-23)"))) -> Afternoon (12-17)
A6: P00664 | B6: acct_034 | C6: Education | D6: 45676 | E6: 20:31 | F6: Carousel | G6: 6265 | H6: 9 | I6: 176 | J6: 0 | K6: 4711 | L6: 3153 | M6: 273 | N6: 17 | O6: 22 | P6: 87 | Q6: 38 | R6: 7 | S6: 20 | T6: Sunday | U6: =(M6+N6+O6+P6)/L6 -> 0.12654615 | V6: =IF(S6<=5,"Late night (0-5)",IF(S6<=11,"Morning (6-11)",IF(S6<=17,"Afternoon (12-17)","Evening (18-23)"))) -> Evening (18-23)
A7: P01316 | B7: acct_004 | C7: Beauty | D7: 45965 | E7: 00:56 | F7: Video | G7: 19609 | H7: 22 | I7: 263 | J7: 1 | K7: 30649 | L7: 17924 | M7: 1342 | N7: 103 | O7: 155 | P7: 364 | Q7: 162 | R7: 15 | S7: 0 | T7: Tuesday | U7: =(M7+N7+O7+P7)/L7 -> 0.10957376 | V7: =IF(S7<=5,"Late night (0-5)",IF(S7<=11,"Morning (6-11)",IF(S7<=17,"Afternoon (12-17)","Evening (18-23)"))) -> Late night (0-5)
A8: P00986 | B8: acct_038 | C8: Food | D8: 45992 | E8: 19:52 | F8: Reel | G8: 11318 | H8: 13 | I8: 111 | J8: 0 | K8: 74380 | L8: 53028 | M8: 2910 | N8: 132 | O8: 201 | P8: 659 | Q8: 1364 | R8: 173 | S8: 19 | T8: Monday | U8: =(M8+N8+O8+P8)/L8 -> 0.073583767 | V8: =IF(S8<=5,"Late night (0-5)",IF(S8<=11,"Morning (6-11)",IF(S8<=17,"Afternoon (12-17)","Evening (18-23)"))) -> Evening (18-23)
A9: P00965 | B9: acct_049 | C9: Fitness | D9: 45909 | E9: 13:01 | F9: Carousel | G9: 31021 | H9: 10 | I9: 105 | J9: 1 | K9: 8002 | L9: 5636 | M9: 355 | N9: 21 | O9: 50 | P9: 117 | Q9: 57 | R9: 4 | S9: 13 | T9: Tuesday | U9: =(M9+N9+O9+P9)/L9 -> 0.096344925 | V9: =IF(S9<=5,"Late night (0-5)",IF(S9<=11,"Morning (6-11)",IF(S9<=17,"Afternoon (12-17)","Evening (18-23)"))) -> Afternoon (12-17)
A10: P00419 | B10: acct_046 | C10: Travel | D10: 45927 | E10: 18:00 | F10: Carousel | G10: 7512 | H10: 6 | I10: 112 | J10: 0 | K10: 21458 | L10: 15969 | M10: 1091 | N10: 55 | O10: 56 | P10: 408 | Q10: 223 | R10: 35 | S10: 18 | T10: Saturday | U10: =(M10+N10+O10+P10)/L10 -> 0.10082034 | V10: =IF(S10<=5,"Late night (0-5)",IF(S10<=11,"Morning (6-11)",IF(S10<=17,"Afternoon (12-17)","Evening (18-23)"))) -> Evening (18-23)
A11: P00181 | B11: acct_056 | C11: Education | D11: 45700 | E11: 07:59 | F11: Image | G11: 43781 | H11: 8 | I11: 297 | J11: 1 | K11: 55284 | L11: 36431 | M11: 1780 | N11: 70 | O11: 263 | P11: 377 | Q11: 305 | R11: 48 | S11: 7 | T11: Wednesday | U11: =(M11+N11+O11+P11)/L11 -> 0.068348385 | V11: =IF(S11<=5,"Late night (0-5)",IF(S11<=11,"Morning (6-11)",IF(S11<=17,"Afternoon (12-17)","Evening (18-23)"))) -> Morning (6-11)
A12: P01300 | B12: acct_033 | C12: Food | D12: 45698 | E12: 21:44 | F12: Reel | G12: 35922 | H12: 16 | I12: 45 | J12: 0 | K12: 147204 | L12: 122458 | M12: 12131 | N12: 282 | O12: 1286 | P12: 2491 | Q12: 2762 | R12: 691 | S12: 21 | T12: Monday | U12: =(M12+N12+O12+P12)/L12 -> 0.13220859 | V12: =IF(S12<=5,"Late night (0-5)",IF(S12<=11,"Morning (6-11)",IF(S12<=17,"Afternoon (12-17)","Evening (18-23)"))) -> Evening (18-23)
A13: P00991 | B13: acct_003 | C13: Beauty | D13: 45661 | E13: 02:52 | F13: Video | G13: 7316 | H13: 15 | I13: 108 | J13: 0 | K13: 1930 | L13: 1138 | M13: 82 | N13: 1 | O13: 3 | P13: 200 | Q13: 16 | R13: 3 | S13: 2 | T13: Saturday | U13: =(M13+N13+O13+P13)/L13 -> 0.2513181 | V13: =IF(S13<=5,"Late night (0-5)",IF(S13<=11,"Morning (6-11)",IF(S13<=17,"Afternoon (12-17)","Evening (18-23)"))) -> Late night (0-5)
... A2001: P01193 | B2001: acct_055 | C2001: Food | D2001: 46009 | E2001: 06:02 | F2001: Reel | G2001: 18366 | H2001: 15 | I2001: 119 | J2001: 1 | K2001: 34094 | L2001: 24655 | M2001: 2613 | N2001: 161 | O2001: 433 | P2001: 331 | Q2001: 348 | R2001: 70 | S2001: 6 | T2001: Thursday | U2001: =(M2001+N2001+O2001+P2001)/L2001 -> 0.1435003 | V2001: =IF(S2001<=5,"Late night (0-5)",IF(S2001<=11,"Morning (6-11)",IF(S2001<=17,"Afternoon (12-17)","Evening (18-23)"))) -> Morning (6-11)

Sheet Summary
A1: Instagram Content Performance - Summary (all values are formulas on the Data sheet)
A2: Engagement rate = (likes + comments + shares + saves) / reach. Data is synthetic proxy data, so results are for practice, not real-world findings.
A4: KPIs
A5: Total posts | B5: =COUNTA(Data!$A$2:$A$2001) -> 2000
A6: Total reach | B6: =SUM(Data!$L$2:$L$2001) -> 59206598
A7: Average reach per post | B7: =AVERAGE(Data!$L$2:$L$2001) -> 29603.299
A8: Average engagement rate | B8: =AVERAGE(Data!$U$2:$U$2001) -> 0.088882095
A10: 1. By post type
A11: Post type | B11: Posts | C11: Avg reach | D11: Avg engagement rate
A12: Reel | B12: =COUNTIF(Data!$F$2:$F$2001,A12) -> 704 | C12: =AVERAGEIF(Data!$F$2:$F$2001,A12,Data!$L$2:$L$2001) -> 43576.183 | D12: =AVERAGEIF(Data!$F$2:$F$2001,A12,Data!$U$2:$U$2001) -> 0.10197066
A13: Carousel | B13: =COUNTIF(Data!$F$2:$F$2001,A13) -> 458 | C13: =AVERAGEIF(Data!$F$2:$F$2001,A13,Data!$L$2:$L$2001) -> 25340.249 | D13: =AVERAGEIF(Data!$F$2:$F$2001,A13,Data!$U$2:$U$2001) -> 0.084670221
A14: Video | B14: =COUNTIF(Data!$F$2:$F$2001,A14) -> 223 | C14: =AVERAGEIF(Data!$F$2:$F$2001,A14,Data!$L$2:$L$2001) -> 24574.404 | D14: =AVERAGEIF(Data!$F$2:$F$2001,A14,Data!$U$2:$U$2001) -> 0.081096837
A15: Image | B15: =COUNTIF(Data!$F$2:$F$2001,A15) -> 615 | C15: =AVERAGEIF(Data!$F$2:$F$2001,A15,Data!$L$2:$L$2001) -> 18606.567 | D15: =AVERAGEIF(Data!$F$2:$F$2001,A15,Data!$U$2:$U$2001) -> 0.079859004
A18: 2. By time of day
A19: Time slot | B19: Posts | C19: Avg reach | D19: Avg engagement rate
A20: Late night (0-5) | B20: =COUNTIF(Data!$V$2:$V$2001,A20) -> 491 | C20: =AVERAGEIF(Data!$V$2:$V$2001,A20,Data!$L$2:$L$2001) -> 18179.413 | D20: =AVERAGEIF(Data!$V$2:$V$2001,A20,Data!$U$2:$U$2001) -> 0.089019876
A21: Morning (6-11) | B21: =COUNTIF(Data!$V$2:$V$2001,A21) -> 497 | C21: =AVERAGEIF(Data!$V$2:$V$2001,A21,Data!$L$2:$L$2001) -> 31143.457 | D21: =AVERAGEIF(Data!$V$2:$V$2001,A21,Data!$U$2:$U$2001) -> 0.089064329
A22: Afternoon (12-17) | B22: =COUNTIF(Data!$V$2:$V$2001,A22) -> 501 | C22: =AVERAGEIF(Data!$V$2:$V$2001,A22,Data!$L$2:$L$2001) -> 29143.102 | D22: =AVERAGEIF(Data!$V$2:$V$2001,A22,Data!$U$2:$U$2001) -> 0.087635137
A23: Evening (18-23) | B23: =COUNTIF(Data!$V$2:$V$2001,A23) -> 511 | C23: =AVERAGEIF(Data!$V$2:$V$2001,A23,Data!$L$2:$L$2001) -> 39533.295 | D23: =AVERAGEIF(Data!$V$2:$V$2001,A23,Data!$U$2:$U$2001) -> 0.089795022
A26: 3. By niche
A27: Niche | B27: Posts | C27: Avg reach | D27: Avg engagement rate
A28: Comedy | B28: =COUNTIF(Data!$C$2:$C$2001,A28) -> 155 | C28: =AVERAGEIF(Data!$C$2:$C$2001,A28,Data!$L$2:$L$2001) -> 51116.387 | D28: =AVERAGEIF(Data!$C$2:$C$2001,A28,Data!$U$2:$U$2001) -> 0.087601248
A29: Fitness | B29: =COUNTIF(Data!$C$2:$C$2001,A29) -> 183 | C29: =AVERAGEIF(Data!$C$2:$C$2001,A29,Data!$L$2:$L$2001) -> 37833.137 | D29: =AVERAGEIF(Data!$C$2:$C$2001,A29,Data!$U$2:$U$2001) -> 0.090956789
A30: Travel | B30: =COUNTIF(Data!$C$2:$C$2001,A30) -> 177 | C30: =AVERAGEIF(Data!$C$2:$C$2001,A30,Data!$L$2:$L$2001) -> 30835.051 | D30: =AVERAGEIF(Data!$C$2:$C$2001,A30,Data!$U$2:$U$2001) -> 0.085412157
A31: Tech | B31: =COUNTIF(Data!$C$2:$C$2001,A31) -> 226 | C31: =AVERAGEIF(Data!$C$2:$C$2001,A31,Data!$L$2:$L$2001) -> 29337.102 | D31: =AVERAGEIF(Data!$C$2:$C$2001,A31,Data!$U$2:$U$2001) -> 0.090896667
A32: Education | B32: =COUNTIF(Data!$C$2:$C$2001,A32) -> 461 | C32: =AVERAGEIF(Data!$C$2:$C$2001,A32,Data!$L$2:$L$2001) -> 29078.62 | D32: =AVERAGEIF(Data!$C$2:$C$2001,A32,Data!$U$2:$U$2001) -> 0.086485904
A33: Fashion | B33: =COUNTIF(Data!$C$2:$C$2001,A33) -> 259 | C33: =AVERAGEIF(Data!$C$2:$C$2001,A33,Data!$L$2:$L$2001) -> 25781.931 | D33: =AVERAGEIF(Data!$C$2:$C$2001,A33,Data!$U$2:$U$2001) -> 0.090232957
A34: Beauty | B34: =COUNTIF(Data!$C$2:$C$2001,A34) -> 362 | C34: =AVERAGEIF(Data!$C$2:$C$2001,A34,Data!$L$2:$L$2001) -> 24195.489 | D34: =AVERAGEIF(Data!$C$2:$C$2001,A34,Data!$U$2:$U$2001) -> 0.089425595
A35: Food | B35: =COUNTIF(Data!$C$2:$C$2001,A35) -> 177 | C35: =AVERAGEIF(Data!$C$2:$C$2001,A35,Data!$L$2:$L$2001) -> 19381.774 | D35: =AVERAGEIF(Data!$C$2:$C$2001,A35,Data!$U$2:$U$2001) -> 0.091909055
A38: 4. Call-to-action (CTA) effect
A39: Has CTA (0=no, 1=yes) | B39: Posts | C39: Avg reach | D39: Avg engagement rate
A40: 0 | B40: =COUNTIF(Data!$J$2:$J$2001,A40) -> 1195 | C40: =AVERAGEIF(Data!$J$2:$J$2001,A40,Data!$L$2:$L$2001) -> 29191.346 | D40: =AVERAGEIF(Data!$J$2:$J$2001,A40,Data!$U$2:$U$2001) -> 0.08951683
A41: 1 | B41: =COUNTIF(Data!$J$2:$J$2001,A41) -> 805 | C41: =AVERAGEIF(Data!$J$2:$J$2001,A41,Data!$L$2:$L$2001) -> 30214.831 | D41: =AVERAGEIF(Data!$J$2:$J$2001,A41,Data!$U$2:$U$2001) -> 0.08793985
A44: 5. Hashtag count groups
A45: Hashtags | B45: Min | C45: Max | D45: Posts | E45: Avg reach
A46: 0-5 | B46: 0 | C46: 5 | D46: =COUNTIFS(Data!$H$2:$H$2001,">="&B46,Data!$H$2:$H$2001,"<="&C46) -> 290 | E46: =AVERAGEIFS(Data!$L$2:$L$2001,Data!$H$2:$H$2001,">="&B46,Data!$H$2:$H$2001,"<="&C46) -> 24402.693
A47: 6-10 | B47: 6 | C47: 10 | D47: =COUNTIFS(Data!$H$2:$H$2001,">="&B47,Data!$H$2:$H$2001,"<="&C47) -> 545 | E47: =AVERAGEIFS(Data!$L$2:$L$2001,Data!$H$2:$H$2001,">="&B47,Data!$H$2:$H$2001,"<="&C47) -> 29120.292
A48: 11-15 | B48: 11 | C48: 15 | D48: =COUNTIFS(Data!$H$2:$H$2001,">="&B48,Data!$H$2:$H$2001,"<="&C48) -> 667 | E48: =AVERAGEIFS(Data!$L$2:$L$2001,Data!$H$2:$H$2001,">="&B48,Data!$H$2:$H$2001,"<="&C48) -> 31170.462
A49: 16+ | B49: 16 | C49: 30 | D49: =COUNTIFS(Data!$H$2:$H$2001,">="&B49,Data!$H$2:$H$2001,"<="&C49) -> 498 | E49: =AVERAGEIFS(Data!$L$2:$L$2001,Data!$H$2:$H$2001,">="&B49,Data!$H$2:$H$2001,"<="&C49) -> 31061.365
A52: 6. Average reach: weekday x hour (heatmap)
...

Sheet Notes
A1: Notes
A2: Source: data/instagram_clean.csv (synthetic proxy dataset, 2,000 posts, 60 accounts, year 2025).
A3: Cleaning already done in Python: 15 duplicate rows removed, missing saves/caption_length filled with the median.
A4: To repeat the cleaning in Excel on the raw file: Data > Remove Duplicates, then filter blanks and fill them.
A5: Engagement rate (Data!U) = (likes + comments + shares + saves) / reach.
A6: Time slot (Data!V) is derived from the hour using nested IF.
A7: Blue numbers on the Summary sheet (hashtag min/max) are inputs you can change.
A8: Pivot-table practice: Insert > PivotTable on the Data sheet, rows = post_type, values = Average of engagement_rate.
